Workbook

Sheet Project Builder
D1: Material list
A2: Category | B2: Sub Category | C2: Type | D2: Description | E2: Item | F2: Price | G2: Qtd | H2: Total | K2: Material Totals
A3: House | B3: Framing | C3: Labor | D3: Carpenters | E3: Hourly (Carp) | F3: 75 | G3: 50 | H3: =F3*G3 -> 3750 | J3: cost | K3: =SUM(H3:H53) -> 7798.15
D4: Labors | E4: Hourly (Labor) | F4: 25 | G4: 20 | H4: =F4*G4 -> 500 | J4: surcharge | K4: 0.2
D5: Job management | E5: Matt per day | F5: 400 | G5: 2 | H5: =F5*G5 -> 800 | J5: sale | K5: =K3*K4+K3 -> 9357.78
C6: Equipment | D6: Debris Removal | E6: Dump tailer rent per day | F6: 200 | G6: 1 | H6: =F6*G6 -> 200
D7: setting trusses | E7: Craine per hr | F7: 400 | G7: 3 | H7: =F7*G7 -> 1200
C8: Materials | D8: Top Bottom Plates | E8: 2x6x16 | F8: =VLOOKUP(E8,'Product $'!B:C,2,FALSE) -> 12.55 | G8: 20 | H8: =F8*G8 -> 251
D9: Wall Studs | E9: 2x4x92 5/8" | F9: =VLOOKUP(E9,'Product $'!B:C,2,FALSE) -> 3.27 | G9: 100 | H9: =F9*G9 -> 327
E10: 2x6x92 5/8" | F10: =VLOOKUP(E10,'Product $'!B:C,2,FALSE) -> 4.86 | G10: 50 | H10: =F10*G10 -> 243
D11: Gream room wall Studs | E11: 2x6x16 | F11: =VLOOKUP(E11,'Product $'!B:C,2,FALSE) -> 12.55 | G11: 26 | H11: =F11*G11 -> 326.3
D12: Accessories | E12: 5 1/2"x50' Sill Seal | F12: =VLOOKUP(E12,'Product $'!B:C,2,FALSE) -> 8.05 | G12: 1 | H12: =F12*G12 -> 8.05
E13: 1/2"x5" Titan anchor bolt | F13: =VLOOKUP(E13,'Product $'!B:C,2,FALSE) -> 5 | G13: 10 | H13: =F13*G13 -> 50
E14: SUBFLOOR Glue 28OZ | F14: =VLOOKUP(E14,'Product $'!B:C,2,FALSE) -> 7.14 | G14: 20 | H14: =F14*G14 -> 142.8
B15: Plumbing | C15: Repeat same idea as above | F15: =VLOOKUP(E15,'Product $'!B:C,2,FALSE) -> 0 | H15: =F15*G15 -> 0
A16: Porch options | B16: Separate category but same idea as above | F16: =VLOOKUP(E16,'Product $'!B:C,2,FALSE) -> 0 | H16: =F16*G16 -> 0
F17: =VLOOKUP(E17,'Product $'!B:C,2,FALSE) -> 0 | H17: =F17*G17 -> 0
F18: =VLOOKUP(E18,'Product $'!B:C,2,FALSE) -> 0 | H18: =F18*G18 -> 0
F19: =VLOOKUP(E19,'Product $'!B:C,2,FALSE) -> 0 | H19: =F19*G19 -> 0
F20: =VLOOKUP(E20,'Product $'!B:C,2,FALSE) -> 0 | H20: =F20*G20 -> 0
F21: =VLOOKUP(E21,'Product $'!B:C,2,FALSE) -> 0 | H21: =F21*G21 -> 0
F22: =VLOOKUP(E22,'Product $'!B:C,2,FALSE) -> 0 | H22: =F22*G22 -> 0
F23: =VLOOKUP(E23,'Product $'!B:C,2,FALSE) -> 0 | H23: =F23*G23 -> 0
F24: =VLOOKUP(E24,'Product $'!B:C,2,FALSE) -> 0 | H24: =F24*G24 -> 0
F25: =VLOOKUP(E25,'Product $'!B:C,2,FALSE) -> 0 | H25: =F25*G25 -> 0
F26: =VLOOKUP(E26,'Product $'!B:C,2,FALSE) -> 0 | H26: =F26*G26 -> 0
F27: =VLOOKUP(E27,'Product $'!B:C,2,FALSE) -> 0 | H27: =F27*G27 -> 0
F28: =VLOOKUP(E28,'Product $'!B:C,2,FALSE) -> 0 | H28: =F28*G28 -> 0
... F53: =VLOOKUP(E53,'Product $'!B:C,2,FALSE) -> 0 | H53: =F53*G53 -> 0

Sheet Jobsite Material List
A1: Description | B1: Item | C1: Qtd
A2: ='Project Builder'!A3 -> House | B2: ='Project Builder'!E3 -> Hourly (Carp) | C2: ='Project Builder'!G3 -> 50
A3: ='Project Builder'!D6 -> Debris Removal | B3: ='Project Builder'!E6 -> Dump tailer rent per day | C3: ='Project Builder'!G6 -> 1
A4: ='Project Builder'!D8 -> Top Bottom Plates | B4: ='Project Builder'!E8 -> 2x6x16 | C4: ='Project Builder'!G8 -> 20
A5: ='Project Builder'!D9 -> Wall Studs | B5: ='Project Builder'!E9 -> 2x4x92 5/8" | C5: ='Project Builder'!G9 -> 100
A6: ='Project Builder'!D10 -> 0 | B6: ='Project Builder'!E10 -> 2x6x92 5/8" | C6: ='Project Builder'!G10 -> 50
A7: ='Project Builder'!D11 -> Gream room wall Studs | B7: ='Project Builder'!E11 -> 2x6x16 | C7: ='Project Builder'!G11 -> 26
A8: ='Project Builder'!D12 -> Accessories | B8: ='Project Builder'!E12 -> 5 1/2"x50' Sill Seal | C8: ='Project Builder'!G12 -> 1
A9: ='Project Builder'!D13 -> 0 | B9: ='Project Builder'!E13 -> 1/2"x5" Titan anchor bolt | C9: ='Project Builder'!G13 -> 10
A10: ='Project Builder'!D14 -> 0 | B10: ='Project Builder'!E14 -> SUBFLOOR Glue 28OZ | C10: ='Project Builder'!G14 -> 20
A11: ='Project Builder'!D15 -> 0 | B11: ='Project Builder'!E15 | C11: ='Project Builder'!G15 -> 0
A12: ='Project Builder'!D16 -> 0 | B12: ='Project Builder'!E16 | C12: ='Project Builder'!G16 -> 0
A13: ='Project Builder'!D17 -> 0 | B13: ='Project Builder'!E17 | C13: ='Project Builder'!G17 -> 0
A14: ='Project Builder'!D18 -> 0 | B14: ='Project Builder'!E18 | C14: ='Project Builder'!G18 -> 0
A15: ='Project Builder'!D19 -> 0 | B15: ='Project Builder'!E19 | C15: ='Project Builder'!G19 -> 0
... A45: ='Project Builder'!D49 -> 0 | B45: ='Project Builder'!E49 | C45: ='Project Builder'!G49 -> 0

Sheet Order List
A1: Order List
A2: Item | B2: Qtd
A3: Hourly (Carp) | B3: 50
A4: Dump tailer rent per day | B4: 1
A5: 2x6x16 | B5: 46
A6: 2x4x92 5/8" | B6: 100
A7: 2x6x92 5/8" | B7: 50
A8: 5 1/2"x50' Sill Seal | B8: 1
A9: 1/2"x5" Titan anchor bolt | B9: 10
A10: SUBFLOOR Glue 28OZ | B10: 20
A161: ='Project Builder'!E95 -> 0 | C161: ='Project Builder'!F95 -> 0
A162: ='Project Builder'!E96 -> 0 | C162: ='Project Builder'!F96 -> 0
A163: ='Project Builder'!E97 -> 0 | C163: ='Project Builder'!F97 -> 0
A164: ='Project Builder'!E98 -> 0 | C164: ='Project Builder'!F98 -> 0
A165: ='Project Builder'!E99 -> 0 | C165: ='Project Builder'!F99 -> 0
A166: ='Project Builder'!E100 -> 0 | C166: ='Project Builder'!F100 -> 0
A167: ='Project Builder'!E101 -> 0 | C167: ='Project Builder'!F101 -> 0
A168: ='Project Builder'!E102 -> 0 | C168: ='Project Builder'!F102 -> 0
A169: ='Project Builder'!E103 -> 0 | C169: ='Project Builder'!F103 -> 0
A170: ='Project Builder'!E104 -> 0 | C170: ='Project Builder'!F104 -> 0

Sheet Income and Expense
A1: Project:
A3: Working Days | C3: Estimated | D3: Actual
C4: 3 | D4: 4
A5: EXPENSES | B5: Quantity | C5: Estimated | D5: Actual | F5: INCOME | G5: Estimated | H5: Actual
A6: Total Non Labor | C6: =C19*B20+C19 -> 9477.78 | D6: =D19*B20+D19 -> 6840 | F6: TOTAL | G6: =C45-C42 -> 11855.88 | H6: =C45-D42 -> 14185.28
A7: Pro Builder | C7: ='Project Builder'!K3 -> 7798.15 | D7: 5600
A8: I Would like this broken into categories | C8: 0 | F8: Employees | G8: =SUM(C32:C36)*B31 -> 626.25 | H8: =SUM(D32:D36)*B31 -> 600
C9: 0 | F9: Materials | G9: =C19*B20 -> 1579.63 | H9: =D19*B20 -> 1140
C10: 0 | F10: Subs | G10: =SUM(C22:C25)*B21 -> 50 | H10: =SUM(D22:D25)*B21 -> 50
C11: =(VLOOKUP(A11,'Other $'!B:C,2,FALSE))*B11 -> 0 | F11: Payout Income | G11: =G6-G8-G9-G10 -> 9600 | H11: =H6-H8-H9-H10 -> 12395.28
C12: =(VLOOKUP(A12,'Other $'!B:C,2,FALSE))*B12 -> 0 | F12: Jessie | G12: =G11*0.15625 -> 1500 | H12: =H11*0.15625 -> 1936.7625
C13: =(VLOOKUP(A13,'Other $'!B:C,2,FALSE))*B13 -> 0
C14: =(VLOOKUP(A14,'Other $'!B:C,2,FALSE))*B14 -> 0
C15: =(VLOOKUP(A15,'Other $'!B:C,2,FALSE))*B15 -> 0
C16: =(VLOOKUP(A16,'Other $'!B:C,2,FALSE))*B16 -> 0
C17: =(VLOOKUP(A17,'Other $'!B:C,2,FALSE))*B17 -> 0 | F17: After Payouts | G17: =G11-SUM(G12:G16) -> 8100 | H17: =H11-SUM(H12:H16) -> 10458.517
A18: Gift | C18: 100 | D18: 100 | F18: Western Skies | G18: =G17/3 -> 2700 | H18: =H17/3 -> 3486.1725
A19: Cost | C19: =SUM(C7:C18) -> 7898.15 | D19: =SUM(D7:D18) -> 5700 | F19: John | G19: =G17/3 -> 2700 | H19: =H17/3 -> 3486.1725
A20: Surcharge | B20: 0.2 | F20: Matt | G20: =G17/3 -> 2700 | H20: =H17/3 -> 3486.1725
A21: Subs | B21: 0.1 | C21: =SUM(C22:C25)*B21+SUM(C22:C25) -> 550 | D21: =SUM(D22:D25)*B21+SUM(D22:D25) -> 550 | F21: Daily Rate | G21: =G20/C4 -> 900 | H21: =H20/D4 -> 871.54312
A22: Plumber | C22: 500 | D22: 500
F24: Total Profit | G24: =G6-SUM(G12:G16) -> 10355.88 | H24: =H6-SUM(H12:H16) -> 12248.517
F25: Western Skies | G25: =G24/3 -> 3451.96 | H25: =H24/3 -> 4082.8392
A26: Partners | C26: =SUM(C27:C30) -> 9600 | F26: John | G26: =G24/3 -> 3451.96 | H26: =H24/3 -> 4082.8392
A27: Matt Per day | C27: =(VLOOKUP(A27,'Other $'!B:C,2,FALSE))*C4 -> 2700 | F27: Matt | G27: =G24/3 -> 3451.96 | H27: =H24/3 -> 4082.8392
A28: John Per day | C28: =(VLOOKUP(A28,'Other $'!B:C,2,FALSE))*C4 -> 2700 | F28: Daily Rate | G28: =G27/C4 -> 1150.6533 | H28: =H27/D4 -> 1020.7098
A29: WSC Per day | C29: =(VLOOKUP(A29,'Other $'!B:C,2,FALSE))*C4 -> 2700
A30: Jessie Per Day | C30: =500*C4 -> 1500
A31: Employees | B31: 0.2 | C31: =SUM(C32:C36)*B31+SUM(C32:C36) -> 3757.5 | D31: =SUM(D32:D36)*B31+SUM(D32:D36) -> 3600
A32: Logan per day $20 | C32: =(VLOOKUP(A32,'Other $'!B:C,2,FALSE))*C4 -> 750 | D32: 800
A33: Elias per day $23.50 | C33: =(VLOOKUP(A33,'Other $'!B:C,2,FALSE))*C4 -> 881.25 | D33: 700
A34: Zook Per day $40 | C34: =(VLOOKUP(A34,'Other $'!B:C,2,FALSE))*C4 -> 1500 | D34: 1500
C35: =(VLOOKUP(A35,'Other $'!B:C,2,FALSE))*C4 -> 0
C36: =(VLOOKUP(A36,'Other $'!B:C,2,FALSE))*C4 -> 0
A37: Bonuses | C37: =SUM(C38:C41) -> 0 | D37: =SUM(D38:D41) -> 0
C38: =(VLOOKUP(A38,'Other $'!B:C,2,FALSE))*C4 -> 0
C39: =(VLOOKUP(A39,'Other $'!B:C,2,FALSE))*C4 -> 0
C40: =(VLOOKUP(A40,'Other $'!B:C,2,FALSE))*C4 -> 0
C41: =(VLOOKUP(A41,'Other $'!B:C,2,FALSE))*C4 -> 0
A42: TOTAL Expenses | C42: =SUM(C38:C41,C32:C36,C22:C25,C19) -> 11529.4 | D42: =SUM(D38:D41,D32:D36,D22:D25,D19) -> 9200
...

Sheet Other $
A1: Other Expenses
A2: Supplyer | B2: Item | C2: Price
C3: 0
A4: Rentals | B4: Skytrack Day | C4: 400
B5: Skytrack Week | C5: 750
B6: Skytrack Month | C6: 2500
B7: Skid Steer Day | C7: 200
B8: Skid Steer Week | C8: 1000
B9: Skid Steer Month | C9: 2000
B10: WSC Skid Steer per hr | C10: 100
B11: 305 Mini Day | C11: 375
B12: 305 Mini Week | C12: 1000
B13: 305 Mini Month | C13: 2000
B14: Roller Packer Day | C14: 300
B15: Roller Packer Week | C15: 1000
B16: Roller Packer Month | C16: 2000
... B18: Porta Potty per week | C18: 105
A19: Vantassel | B19: Crane per hr | C19: 150
A20: Victor Transfer | B20: Dump Trailer Load | C20: 120
A21: Out Of Town | B21: Meals | C21: 120
B22: Hotel | C22: 300
B23: Fuel (Miles) | C23: 1
B24: OUT Employee Bounus | C24: 100
A25: Labor | B25: Logan per day $20 | C25: =200*1.25 -> 250 | D25: =C25*1.2 -> 300 | E25: Crew Cost | F25: =SUM(C25:C30) -> 3743.75
B26: Elias per day $23.50 | C26: =235*1.25 -> 293.75 | D26: =C26*1.2 -> 352.5 | E26: Crew Rate | F26: =SUM(D25:D30) -> 3952.5
B27: Zook Per day $40 | C27: =400*1.25 -> 500 | D27: =C27*1.2 -> 600
B28: John Per day | C28: 900 | D28: =C28 -> 900
B29: Matt Per day | C29: 900 | D29: =C29 -> 900
B30: WSC Per day | C30: 900 | D30: =C30 -> 900
B31: Hourly Labor $100 | C31: 100

Sheet Product $
A1: Price List
A2: Type | B2: Item | C2: Price
C3: 0
B4: 2x4x92 5/8" | C4: ='MASSA $'!C2 -> 3.27
B5: 2x4x104 5/8" | C5: ='MASSA $'!C3 -> 4.27
B6: 2x4x116" | C6: ='MASSA $'!C4 -> 4.62
B7: 2x4x8 | C7: ='MASSA $'!C5 -> 4.18
B8: 2x4x10 | C8: ='MASSA $'!C6 -> 5.24
B9: 2x4x12 | C9: ='MASSA $'!C7 -> 6.28
B10: 2x4x14 | C10: ='MASSA $'!C8 -> 6.28
B11: 2x4x16 | C11: ='MASSA $'!C9 -> 8.37
B12: 2x4x18 | C12: ='MASSA $'!C10 -> CALL
B13: 2x4x20 | C13: ='MASSA $'!C11 -> 12.09
B14: 2x4x16 PT | C14: ='MASSA $'!C14*16 -> #VALUE!
B15: 2x6x92 5/8" | C15: ='MASSA $'!G2 -> 4.86
B16: 2x6x104 5/8" | C16: ='MASSA $'!G3 -> 6.4
B17: 2x6x116" | C17: ='MASSA $'!G4 -> 7.23
B18: 2x6x8 | C18: ='MASSA $'!G5 -> 6.28
B19: 2x6x10 | C19: ='MASSA $'!G6 -> 7.85
B20: 2x6x12 | C20: ='MASSA $'!G7 -> 9.42
B21: 2x6x14 | C21: ='MASSA $'!G8 -> 10.98
B22: 2x6x16 | C22: ='MASSA $'!G9 -> 12.55
B23: 2x6x18 | C23: ='MASSA $'!G10 -> CALL
B24: 2x6x20 | C24: ='MASSA $'!G11 -> 18.15
B25: 2x6x16 PT | C25: ='MASSA $'!C15*16 -> 12.96
B26: 2x6x12 T&G Pine | C26: 18
B27: 2x6x16 T&G Pine | C27: 24
B28: 2x8x8 | C28: ='MASSA $'!K2 -> 11.44
B29: 2x8x10 | C29: ='MASSA $'!K3 -> 14.3
B30: 2x8x12 | C30: ='MASSA $'!K4 -> 17.16
B31: 2x8x14 | C31: ='MASSA $'!K5 -> 20.02
B32: 2x8x16 | C32: ='MASSA $'!K6 -> 22.89
B33: 2x8x18 | C33: ='MASSA $'!K7 -> CALL
B34: 2x8x20 | C34: ='MASSA $'!K8 -> 31.87
B35: 2x8x16 PT | C35: ='MASSA $'!C16*16 -> 17.6
B36: 2x10x8 | C36: ='MASSA $'!O2 -> 14.3
B37: 2x10x10 | C37: ='MASSA $'!O3 -> 17.88
B38: 2x10x12 | C38: ='MASSA $'!O4 -> 21.45
B39: 2x10x14 | C39: ='MASSA $'!O5 -> 25.02
B40: 2x10x16 | C40: ='MASSA $'!O6 -> 28.61
...

Sheet MASSA $
A1: 2 X 4 | B1: Bd. Ft. | C1: Each | E1: 2 X 6 | F1: Bd. Ft. | G1: Each | I1: 2 X 8 | J1: Bd. Ft. | K1: Each | M1: 2 X 10 | N1: Bd. Ft. | O1: Each | Q1: 2x12 | R1: Bd. Ft. | S1: Each | U1: Sheeting | W1: Each | Y1: BCI & LSL | AA1: LF
A2: x 92 | B2: Studs | C2: 3.27 | E2: x 92 | F2: Studs | G2: 4.86 | I2: x 8 | J2: 10.67 | K2: 11.44 | M2: x 8 | N2: 13.33 | O2: 14.3 | Q2: x 8 | R2: 16 | S2: 17.45 | U2: 3/8 CDX | W2: 17.65 | Y2: 11-7/8" BCI 5000 | AA2: 2.84
A3: x 104 | B3: Studs | C3: 4.27 | E3: x 104 | F3: Studs | G3: 6.4 | I3: x 10 | J3: 13.33 | K3: 14.3 | M3: x 10 | N3: 16.67 | O3: 17.88 | Q3: x 10 | R3: 20 | S3: 21.82 | U3: 1/2 CDX | W3: 20.79 | Y3: 1-1/8"x11-7/8" Rim | AA3: 2.5
A4: x116 | B4: Studs | C4: 4.62 | E4: x116 | F4: Studs | G4: 7.23 | I4: x 12 | J4: 16 | K4: 17.16 | M4: x 12 | N4: 20 | O4: 21.45 | Q4: x 12 | R4: 24 | S4: 26.18 | U4: 5/8 CDX | W4: 27.07 | Y4: 1-1/2"x5-1/2" LSL | AA4: 1.97
A5: x 8 | B5: 5.33 | C5: 4.18 | E5: x 8 | F5: 8 | G5: 6.28 | I5: x 14 | J5: 18.67 | K5: 20.02 | M5: x 14 | N5: 23.33 | O5: 25.02 | Q5: x 14 | R5: 28 | S5: 30.54 | U5: 3/4 CDX | W5: 32.76
A6: x 10 | B6: 6.67 | C6: 5.24 | E6: x 10 | F6: 10 | G6: 7.85 | I6: x 16 | J6: 21.33 | K6: 22.89 | M6: x 16 | N6: 26.67 | O6: 28.61 | Q6: x 16 | R6: 32 | S6: 38.84 | U6: 3/4 T&G Ply | W6: 39.62
A7: x 12 | B7: 8 | C7: 6.28 | E7: x 12 | F7: 12 | G7: 9.42 | I7: x 18 | J7: 24 | K7: CALL | M7: x 18 | N7: 30 | O7: CALL | Q7: x 18 | R7: 36 | S7: CALL | U7: 7/16 OSB | W7: 9.95
A8: x 14 | B8: 9.33 | C8: 6.28 | E8: x 14 | F8: 14 | G8: 10.98 | I8: x 20 | J8: 26.67 | K8: 31.87 | M8: x 20 | N8: 33.3 | O8: 39.84 | Q8: x 20 | R8: 40 | S8: 60.8 | U8: 15/32 OSB | W8: 11.8
A9: x 16 | B9: 10.67 | C9: 8.37 | E9: x 16 | F9: 16 | G9: 12.55 | U9: 19/32 OSB | W9: 15.4
A10: x 18 | B10: 12 | C10: CALL | E10: x 18 | F10: 18 | G10: CALL | U10: 3/4 T&G OSB Edge | W10: 18.6
A11: x 20 | B11: 13.3 | C11: 12.09 | E11: x 20 | F11: 20 | G11: 18.15 | U11: 3/4 TG Edge Gold | W11: 21.2
U12: 7/16 OSB 4'X9' | W12: 15.75
A14: Treated | C14: LF | E14: Felt / Roofing | G14: Each | I14: EDCO WHT/BLK | K14: Each | M14: Insulation | O14: Sq. Ft. | Q14: Sheetrock | S14: Each | U14: Particle Board | W14: Each | Y14: LVL | AA14: 1 5/16 | AB14: 1 3/4 | AC14: 3 1/2 | AD14: 5 1/4
A15: 2 x 4 | C15: 0.81 | E15: 30# Felt | G15: 26.6 | I15: 12' F-Channel | K15: 18.76 | M15: 3 1/2" Kraft R11 | O15: 0.47 | Q15: 1/2 x 12' | S15: 23.09 | U15: 3/8" | W15: 24.32 | Y15: 9 1/2" | AB15: 6.72 | AC15: 14.36 | AD15: 22
A16: 2 x 6 | C16: 1.1 | E16: Ice & Water Shield | G16: 73.88 | I16: 12' J-Channel | K16: 10.76 | M16: 3 1/2" Kraft R13 | O16: 0.57 | Q16: 5/8 x 12' | S16: 24.51 | U16: 1/2" | W16: 25.34 | Y16: 11 7/8" | AA16: 4.94 | AB16: 7.58 | AC16: 17.13 | AD16: 27.02
A17: 2 x 8 | C17: 1.48 | E17: TUL 10SQ UDL | G17: 155.8 | I17: 10' D-Metal | K17: 12.73 | M17: 6 1/4" Kraft R19 | O17: 0.68 | Q17: 1/2 x 8' | S17: 15.39 | U17: 5/8" | W17: 28.88 | Y17: 14" | AB17: 10.18 | AC17: 20.78 | AD17: 31.49
A18: 2 x 10 | C18: 2.29 | E18: GAF TigerPaw 10SQ | G18: 183.61 | I18: 16"x12' Soffit | K18: 33.91 | M18: 5 1/2" Kraft R21 | O18: 1.01 | Q18: 5/8 x 8' | S18: 16.34 | U18: 3/4" | W18: 29.83 | Y18: 16" | AB18: 12.28 | AC18: Spl Ordr | AD18: Spl Ordr
A19: 2 x 12 | C19: 2.56 | E19: GAF High Definition | G19: 116.85 | I19: 6"x12' Steel Fascia | K19: 19.86 | M19: 5 1/2" Unfaced R21 | O19: 0.96 | Q19: 1/2 X 8' Water | S19: 18.81 | U19: 1/2 HD | W19: 22.13 | Y19: 18" | AB19: 14.56
A20: 4 x 4 | C20: 2.01 | E20: Malarkey Highlander | G20: 125.4 | M20: 10" Kraft R30 | O20: 1.12 | Q20: Add $2.50/ea for stocking | U20: 3/4 HD | W20: 29.52
A21: 6 x 6 | C21: 5.33 | E21: Add $5.00/[] for Boom Truck | M21: 12" Kraft R38 | O21: 1.33
M22: Knauf Jetstream | O22: 53.20/bag
A24: Siding | C24: Each | E24: Lap & Soffit OSB | G24: Each | I24: Hardiplank | K24: Each | M24: LP Trim | O24: Each | Q24: Pine | S24: LF | U24: Cedar | W24: LF | Y24: Glu lam | AA24: 3 1/2 | AB24: 5 1/2 | AC24: 3 1/8 | AD24: 5 1/8
A25: 3/8" Roughsawn | C25: 66.11 | E25: 3/8 x 6" x16' | G25: 9.72 | I25: 6" x 12' | K25: CALL | M25: 4/4 x 2 x16 | O25: 7.95 | Q25: 1 x 4 #2 Pine | S25: 0.77 | U25: 1 x 4 | W25: 0.92 | Y25: 5-1/2" | AA25: Spl Ordr | AB25: 13.34 | AC25: Spl Ordr | AD25: 13.18
A26: Breckenridge 8" OC 4x8 | C26: CALL | E26: 3/8 x 8" x 16' | G26: 12.25 | I26: 8" x 12' | K26: 13.3 | M26: 19/32 x 3 x 16 | O26: 10.9 | Q26: 1 x 6 #2 Pine | S26: 1.26 | U26: 1 x 6 | W26: 1.74 | Y26: 7-1/2" | AA26: 11.33 | AB26: 15.14 | AC26: 11.58 | AD26: 15.94
A27: LP Panel 3/8x4x8 8" OC | C27: 38.01 | E27: 3/8 x 12" x 16' | G27: 19.69 | M27: 4/4 x 4 x 16 | O27: 13.72 | Q27: 1 x 8 #2 Pine | S27: 1.44 | U27: 1 x 8 | W27: CALL | Y27: 9" | AA27: 12.97 | AB27: 17.64 | AC27: 13.52 | AD27: 18.62
A28: LP Panel 7/16x4x8 S/L | C28: 53.23 | E28: 3/8"x16"x16' Vented | G28: 40.07 | M28: 4/4 x 6 x 16 | O28: 21.29 | Q28: 1 x 10 #2 Pine | S28: 1.74 | U28: 1 x 10 | W28: CALL | Y28: 11-7/8" | AA28: 17.26 | AB28: 23.49 | AC28: 18 | AD28: 24.8
A29: LP Panel 7/16x4x9 S/L | C29: 70.21 | E29: 3/8"x16"x16' Solid | G29: 33.57 | M29: 4/4 x 8 x 16 | O29: 29.98 | Q29: 1 x 12 #2 Pine | S29: 2.57 | U29: 1 x 12 | W29: CALL | Y29: 15" | AA29: 20.83 | AB29: 29.43 | AC29: 23.1 | AD29: 32.49
A30: LP Soffit 3/8"x4'x8' | C30: 42.07 | E30: 3/8"x24"x16' Vented | G30: 61.37 | M30: 4/4 x 10 x 16 | O30: 40.58 | Q30: Fir | S30: LF | U30: 5/4 x 8 RBT | W30: CALL | Y30: 18" | AA30: 28.13 | AB30: 36.14 | AC30: Spl Ordr | AD30: 38.92
E31: 3/8"x24"x16' Solid | G31: 55.02 | M31: 4/4 x 12 x 16 | O31: 48.7 | Q31: 1 x 4 Select Knotty | S31: 0.63 | U31: 11/16 x 8 bevel | W31: CALL
M32: 5/4 x 3 x 16 | O32: 14.87 | Q32: 1 x 6 Select Knotty | S32: 1.26
M33: 5/4 x 4 x 16 | O33: 17.97 | Q33: 1 x 8 Select Knotty | S33: 1.93
M34: 5/4 x 6 x 16 | O34: 26.81
M35: 5/4 x 8 x 16 | O35: 38.2
M36: 5/4 x 10 x 16 | O36: 50.68
M37: 5/4 x 12 x 16 | O37: 63.13
A39: Stock Decking | C39: LF | E39: MDF | G39: Each | I39: Hemlock | K39: LF | M39: MDF Moulding | O39: Each
A40: Cedar 5/4x6x16' | C40: 2.47 | E40: 1 x 2 x 16' | G40: 7.19 | I40: 1 X 3 Vertical Grain | K40: 1.9 | M40: 356 2 1/2"x16' | O40: 9.46
A41: Cedar 2x2x3' | C41: 0.67 | E41: 1 x 3 x 16' | G41: 8.31 | I41: 1 x 4 Vertical Grain | K41: 2.01 | M41: 444 3 1/2"x16' | O41: 16.33
A42: 2x6x16' DFL | C42: 0.92 | E42: 1 x 4 x 16' | G42: 9.99 | I42: 1 x 5 Vertical Grain | K42: 3.23 | M42: 535 3 1/2"x16' | O42: 21.55
A43: TimberTech Edge 1-Tone | C43: CALL | E43: 1 x 5 x 16' | G43: 17.43 | I43: 1 X 6 Vertical Grain | K43: 4.7 | M43: 545 5"x16' | O43: 23.84
...

Sheet Order List (2)
A1: Order List
A2: Item | B2: Qtd
A161: ='Project Builder'!E95 -> 0 | C161: ='Project Builder'!F95 -> 0
A162: ='Project Builder'!E96 -> 0 | C162: ='Project Builder'!F96 -> 0
A163: ='Project Builder'!E97 -> 0 | C163: ='Project Builder'!F97 -> 0
A164: ='Project Builder'!E98 -> 0 | C164: ='Project Builder'!F98 -> 0
A165: ='Project Builder'!E99 -> 0 | C165: ='Project Builder'!F99 -> 0
A166: ='Project Builder'!E100 -> 0 | C166: ='Project Builder'!F100 -> 0
A167: ='Project Builder'!E101 -> 0 | C167: ='Project Builder'!F101 -> 0
A168: ='Project Builder'!E102 -> 0 | C168: ='Project Builder'!F102 -> 0
A169: ='Project Builder'!E103 -> 0 | C169: ='Project Builder'!F103 -> 0
A170: ='Project Builder'!E104 -> 0 | C170: ='Project Builder'!F104 -> 0
